<?xml version="1.0" encoding="utf-8"?>
<robot
  name="rm_65_description">
  <link
    name="base_link">
    <inertial>
      <origin
        xyz="-0.000433277303987328 -3.54664423471128E-05 0.0599427668933796"
        rpy="0 0 0" />
      <mass
        value="0.841070778135659" />
      <inertia
        ixx="0.0017261110801622"
        ixy="2.52746264980217E-06"
        ixz="-3.67690303614961E-05"
        iyy="0.00170987405835604"
        iyz="1.67996364994424E-06"
        izz="0.000904023422915791" />
    </inertial>
    <visual>
      <origin
        xyz="0 0 0"
        rpy="0 0 0" />
      <geometry>
        <mesh
          filename="/home/wangwei/ros2_ws/src/ros2_rm_robot/rm_description/meshes/rm_65_arm/base_link.STL" />
      </geometry>
      <material
        name="">
        <color
          rgba="1 1 1 1" />
      </material>
    </visual>
    <collision>
      <origin
        xyz="0 0 0"
        rpy="0 0 0" />
      <geometry>
        <mesh
          filename="/home/wangwei/ros2_ws/src/ros2_rm_robot/rm_description/meshes/rm_65_arm/base_link.STL" />
      </geometry>
    </collision>
  </link>
  <link
    name="Link1">
    <inertial>
      <origin
        xyz="1.2226305431569E-08 0.0211079974844683 -0.0251854220842269"
        rpy="0 0 0" />
      <mass
        value="0.593563443690403" />
      <inertia
        ixx="0.00126614120341847"
        ixy="-1.294980943835E-08"
        ixz="-9.80120923066996E-09"
        iyy="0.00118168178300364"
        iyz="-0.00021121727444415"
        izz="0.00056135241627747" />
    </inertial>
    <visual>
      <origin
        xyz="0 0 0"
        rpy="0 0 0" />
      <geometry>
        <mesh
          filename="/home/wangwei/ros2_ws/src/ros2_rm_robot/rm_description/meshes/rm_65_arm/link1.STL" />
      </geometry>
      <material
        name="">
        <color
          rgba="1 1 1 1" />
      </material>
    </visual>
    <collision>
      <origin
        xyz="0 0 0"
        rpy="0 0 0" />
      <geometry>
        <mesh
          filename="/home/wangwei/ros2_ws/src/ros2_rm_robot/rm_description/meshes/rm_65_arm/link1.STL" />
      </geometry>
    </collision>
  </link>
  <joint
    name="joint1"
    type="revolute">
    <origin
      xyz="0 0 0.2405"
      rpy="0 0 0" />
    <parent
      link="base_link" />
    <child
      link="Link1" />
    <axis
      xyz="0 0 1" />
    <limit
      lower="-3.1"
      upper="3.1"
      effort="60"
      velocity="3.14" />
  </joint>
  <link
    name="Link2">
    <inertial>
      <origin
        xyz="0.152256463426163 4.75383656106654E-07 -0.00620260383607792"
        rpy="0 0 0" />
      <mass
        value="0.864175046869043" />
      <inertia
        ixx="0.00089150298478414"
        ixy="-2.23268489334765E-08"
        ixz="0.00156246461035015"
        iyy="0.00733754343083901"
        iyz="6.28110889329165E-09"
        izz="0.00697869103915473" />
    </inertial>
    <visual>
      <origin
        xyz="0 0 0"
        rpy="0 0 0" />
      <geometry>
        <mesh
          filename="/home/wangwei/ros2_ws/src/ros2_rm_robot/rm_description/meshes/rm_65_arm/link2.STL" />
      </geometry>
      <material
        name="">
        <color
          rgba="1 1 1 1" />
      </material>
    </visual>
    <collision>
      <origin
        xyz="0 0 0"
        rpy="0 0 0" />
      <geometry>
        <mesh
          filename="/home/wangwei/ros2_ws/src/ros2_rm_robot/rm_description/meshes/rm_65_arm/link2.STL" />
      </geometry>
    </collision>
  </link>
  <joint
    name="joint2"
    type="revolute">
    <origin
      xyz="0 0 0"
      rpy="1.5708 -1.5708 0" />
    <parent
      link="Link1" />
    <child
      link="Link2" />
    <axis
      xyz="0 0 1" />
    <limit
      lower="-2.268"
      upper="2.268"
      effort="60"
      velocity="3.14" />
  </joint>
  <link
    name="Link3">
    <inertial>
      <origin
        xyz="5.05312670989961E-06 -0.0595925663694732 0.010569069212336"
        rpy="0 0 0" />
      <mass
        value="0.289633681624654" />
      <inertia
        ixx="0.00063737100450158"
        ixy="-7.05261293649751E-08"
        ixz="-3.86643272239426E-08"
        iyy="0.00015648388095025"
        iyz="-0.00014461035994916"
        izz="0.000614178164773085" />
    </inertial>
    <visual>
      <origin
        xyz="0 0 0"
        rpy="0 0 0" />
      <geometry>
        <mesh
          filename="/home/wangwei/ros2_ws/src/ros2_rm_robot/rm_description/meshes/rm_65_arm/link3.STL" />
      </geometry>
      <material
        name="">
        <color
          rgba="1 1 1 1" />
      </material>
    </visual>
    <collision>
      <origin
        xyz="0 0 0"
        rpy="0 0 0" />
      <geometry>
        <mesh
          filename="/home/wangwei/ros2_ws/src/ros2_rm_robot/rm_description/meshes/rm_65_arm/link3.STL" />
      </geometry>
    </collision>
  </link>
  <joint
    name="joint3"
    type="revolute">
    <origin
      xyz="0.256 0 0"
      rpy="0 0 1.5708" />
    <parent
      link="Link2" />
    <child
      link="Link3" />
    <axis
      xyz="0 0 1" />
    <limit
      lower="-2.355"
      upper="2.355"
      effort="30"
      velocity="3.92" />
  </joint>
  <link
    name="Link4">
    <inertial>
      <origin
        xyz="1.15516617405898E-06 -0.0180424468598241 -0.0215394748352687"
        rpy="0 0 0" />
      <mass
        value="0.239419768320061" />
      <inertia
        ixx="0.000285938919722783"
        ixy="3.07101359163101E-09"
        ixz="-2.21994118981953E-09"
        iyy="0.000262727540304212"
        iyz="4.4236583260078E-05"
        izz="0.000119888082791859" />
    </inertial>
    <visual>
      <origin
        xyz="0 0 0"
        rpy="0 0 0" />
      <geometry>
        <mesh
          filename="/home/wangwei/ros2_ws/src/ros2_rm_robot/rm_description/meshes/rm_65_arm/link4.STL" />
      </geometry>
      <material
        name="">
        <color
          rgba="1 1 1 1" />
      </material>
    </visual>
    <collision>
      <origin
        xyz="0 0 0"
        rpy="0 0 0" />
      <geometry>
        <mesh
          filename="/home/wangwei/ros2_ws/src/ros2_rm_robot/rm_description/meshes/rm_65_arm/link4.STL" />
      </geometry>
    </collision>
  </link>
  <joint
    name="joint4"
    type="revolute">
    <origin
      xyz="0 -0.21 0"
      rpy="1.5708 0 0" />
    <parent
      link="Link3" />
    <child
      link="Link4" />
    <axis
      xyz="0 0 1" />
    <limit
      lower="-3.1"
      upper="3.1"
      effort="10"
      velocity="3.92" />
  </joint>
  <link
    name="Link5">
    <inertial>
      <origin
        xyz="3.19794786262152E-06 -0.0593808368101458 0.00736804250989326"
        rpy="0 0 0" />
      <mass
        value="0.218799761431678" />
      <inertia
        ixx="0.000350540363914072"
        ixy="-3.41781619975602E-08"
        ixz="-1.77056457224373E-08"
        iyy="0.000104927867487581"
        iyz="-7.82431228461971E-05"
        izz="0.000334482418423629" />
    </inertial>
    <visual>
      <origin
        xyz="0 0 0"
        rpy="0 0 0" />
      <geometry>
        <mesh
          filename="/home/wangwei/ros2_ws/src/ros2_rm_robot/rm_description/meshes/rm_65_arm/link5.STL" />
      </geometry>
      <material
        name="">
        <color
          rgba="1 1 1 1" />
      </material>
    </visual>
    <collision>
      <origin
        xyz="0 0 0"
        rpy="0 0 0" />
      <geometry>
        <mesh
          filename="/home/wangwei/ros2_ws/src/ros2_rm_robot/rm_description/meshes/rm_65_arm/link5.STL" />
      </geometry>
    </collision>
  </link>
  <joint
    name="joint5"
    type="revolute">
    <origin
      xyz="0 0 0"
      rpy="-1.5708 0 0" />
    <parent
      link="Link4" />
    <child
      link="Link5" />
    <axis
      xyz="0 0 1" />
    <limit
      lower="-2.233"
      upper="2.233"
      effort="10"
      velocity="3.92" />
  </joint>

    <joint
    name="joint6"
    type="revolute">
    <origin
      xyz="0 -0.144 0"
      rpy="1.5708 0 0" />
    <parent
      link="Link5" />
    <child
      link="Link6" />
    <axis
      xyz="0 0 1" />
    <limit
      lower="-6.28"
      upper="6.28"
      effort="10"
      velocity="3.92" />
  </joint>
  <link
    name="Link6">
    <inertial>
      <origin
        xyz="0.000714234511756999 -0.000396718732824521 -0.0126723660946126"
        rpy="0 0 0" />
      <mass
        value="0.0649018034311231" />
      <inertia
        ixx="2.02766547502765E-05"
        ixy="-1.32505200276849E-06"
        ixz="-2.5845091522508E-08"
        iyy="1.87986725225022E-05"
        iyz="3.39471452125439E-09"
        izz="3.17885459163081E-05" />
    </inertial>
    <visual>
      <origin
        xyz="0 0 0"
        rpy="0 0 0" />
      <geometry>
        <mesh
          filename="/home/wangwei/ros2_ws/src/ros2_rm_robot/rm_description/meshes/rm_65_arm/link6.STL" />
      </geometry>
      <material
        name="">
        <color
          rgba="1 1 1 1" />
      </material>
    </visual>
    <collision>
      <origin
        xyz="0 0 0"
        rpy="0 0 0" />
      <geometry>
        <mesh
          filename="/home/wangwei/ros2_ws/src/ros2_rm_robot/rm_description/meshes/rm_65_arm/link6.STL" />
      </geometry>
    </collision>
  </link>

  <joint
    name="joint7"
    type="fixed">
    <origin xyz="-0.045 -0.029 0" rpy="0 0 0" />
    <parent
      link="Link6" />
    <child
      link="Camera_base_link" />
  </joint>

  <link
    name="Camera_base_link">
    <inertial>
      <origin
        xyz="0 0 0"
        rpy="0 0 0" />
      <mass
        value="0.02" />
      <inertia ixx="0" ixy="0" ixz="0" iyy="0" iyz="0" izz="0" />
    </inertial>
    <visual>
      <origin
        xyz="0 0 0"
        rpy="0 0 0" />
      <geometry>
        <mesh
          filename="/home/wangwei/ros2_ws/src/ros2_rm_robot/rm_description/meshes/rm_65_arm/camera_stander_no_hole.STL" />
      </geometry>
      <material name="custom_color">
        <color rgba="0 1 0 1" /> <!-- Green color, fully opaque -->
      </material>
    </visual>
    <collision>
      <origin
        xyz="0 0 0"
        rpy="0 0 0" />
      <geometry>
        <mesh
          filename="/home/wangwei/ros2_ws/src/ros2_rm_robot/rm_description/meshes/rm_65_arm/camera_stander_no_hole.STL" />
      </geometry>
    </collision>
  </link>



  <!-- 添加夹爪部分 -->
  <joint name="gripper_base_joint" type="fixed">
    <origin xyz="0.045 0.039 0.051" rpy="-1.5708 -1.5708 0" />
    <parent link="Camera_base_link" />
    <child link="gripper_base_link" />
  </joint>

  <link name="gripper_base_link">
    <inertial>
      <origin xyz="0.00339303654278191 -2.1205433560656E-05 -0.0099185365078758" rpy="0 0 0" />
      <mass value="0.105853592307918" />
      <inertia ixx="3.93795927851199E-05" ixy="-8.7395226509728E-08" ixz="5.91928672040786E-07" iyy="0.000106376720416166" iyz="-1.82858764303774E-10" izz="0.000125852616063213" />
    </inertial>
    <visual>
      <origin xyz="0 0 0" rpy="0 0 0" />
      <geometry>
        <mesh filename="/home/wangwei/ros2_ws/src/ros2_rm_robot/rm_description/meshes/gripper/base_link.STL" />
      </geometry>
      <material name="">
        <color rgba="0.894117647058823 0.913725490196078 0.929411764705882 1" />
      </material>
    </visual>
    <collision>
      <origin xyz="0 0 0" rpy="0 0 0" />
      <geometry>
        <mesh filename="/home/wangwei/ros2_ws/src/ros2_rm_robot/rm_description/meshes/gripper/base_link.STL" />
      </geometry>
    </collision>
  </link>

  <joint name="gripper_joint1" type="revolute">
    <origin xyz="0.036 -0.04 -0.019" rpy="0 0 -0.30719" />
    <parent link="gripper_base_link" />
    <child link="gripper_finger1_link1" />
    <axis xyz="0 0 1" />
    <limit lower="0" upper="1" effort="1" velocity="1" />
  </joint>

  <link name="gripper_finger1_link1">
    <inertial>
      <origin xyz="0.0164149658242926 0.00898193900447147 0.00898193900447147" rpy="0 0 0" />
      <mass value="0.00647716099397792" />
      <inertia ixx="2.95068972140683E-07" ixy="8.63208170411155E-13" ixz="-1.92008628754607E-09" iyy="1.69979619476872E-06" iyz="-1.99232397395103E-13" izz="1.45016449434989E-06" />
    </inertial>
    <visual>
      <origin xyz="0 0 0" rpy="0 0 0" />
      <geometry>
        <mesh filename="/home/wangwei/ros2_ws/src/ros2_rm_robot/rm_description/meshes/gripper/Link1.STL" />
      </geometry>
      <material name="">
        <color rgba="0.894117647058823 0.913725490196078 0.929411764705882 1" />
      </material>
    </visual>
    <collision>
      <origin xyz="0 0 0" rpy="0 0 0" />
      <geometry>
        <mesh filename="/home/wangwei/ros2_ws/src/ros2_rm_robot/rm_description/meshes/gripper/Link1.STL" />
      </geometry>
    </collision>
  </link>

  <joint
    name="finger1_link1_finger1_link2"
    type="revolute">
    <origin
      xyz="0.042 0 0.003"
      rpy="5.0393E-16 5.6225E-16 0.30719" />
    <parent
      link="gripper_finger1_link1" />
    <child
      link="gripper_finger1_link2" />
    <axis
      xyz="0 0 1" />
    <limit
      lower="-1"
      upper="0"
      effort="1"
      velocity="1" />
  </joint>

  <link
    name="gripper_finger1_link2">
    <inertial>
      <origin
        xyz="0.011366555972498 0.0118642725662323 0.0060000073930068"
        rpy="0 0 0" />
      <mass
        value="0.0127543420299361" />
      <inertia
        ixx="5.68538478020233E-07"
        ixy="-2.68012262729007E-07"
        ixz="9.34125984931838E-13"
        iyy="1.45145776457487E-06"
        iyz="9.34355360561326E-13"
        izz="1.50564598220449E-06" />
    </inertial>
    <visual>
      <origin
        xyz="0 0 0"
        rpy="0 0 0" />
      <geometry>
        <mesh
          filename="/home/wangwei/ros2_ws/src/ros2_rm_robot/rm_description/meshes/gripper/Link11.STL" />
      </geometry>
      <material
        name="">
        <color
          rgba="0.894117647058823 0.913725490196078 0.929411764705882 1" />
      </material>
    </visual>
    <collision>
      <origin
        xyz="0 0 0"
        rpy="0 0 0" />
      <geometry>
        <mesh
          filename="/home/wangwei/ros2_ws/src/ros2_rm_robot/rm_description/meshes/gripper/Link11.STL" />
      </geometry>
    </collision>
  </link>


  <joint name="gripper_joint2" type="revolute">
    <origin xyz="0.036 0.04 -0.019" rpy="0 0 0.30719" />
    <parent link="gripper_base_link" />
    <child link="gripper_finger2_link1" />
    <axis xyz="0 0 1" />
    <limit lower="-1" upper="0" effort="1" velocity="1" />
  </joint>

  <link name="gripper_finger2_link1">
    <inertial>
      <origin xyz="0.0164149658242926 0.00898193900447147 0.00898193900447147" rpy="0 0 0" />
      <mass value="0.00647716099397792" />
      <inertia ixx="2.95068972140683E-07" ixy="8.63208170411155E-13" ixz="-1.92008628754607E-09" iyy="1.69979619476872E-06" iyz="-1.99232397395103E-13" izz="1.45016449434989E-06" />
    </inertial>
    <visual>
      <origin xyz="0 0 0" rpy="0 0 0" />
      <geometry>
        <mesh filename="/home/wangwei/ros2_ws/src/ros2_rm_robot/rm_description/meshes/gripper/Link2.STL" />
      </geometry>
      <material name="">
        <color rgba="0.894117647058823 0.913725490196078 0.929411764705882 1" />
      </material>
    </visual>
    <collision>
      <origin xyz="0 0 0" rpy="0 0 0" />
      <geometry>
        <mesh filename="/home/wangwei/ros2_ws/src/ros2_rm_robot/rm_description/meshes/gripper/Link2.STL" />
      </geometry>
    </collision>
  </link>

  <joint
    name="finger2_link1_finger2_link2"
    type="revolute">
    <origin
      xyz="0.042 0 0.015"
      rpy="-3.641E-16 2.4584E-16 2.8344" />
    <parent
      link="gripper_finger2_link1" />
    <child
      link="gripper_finger2_link2" />
    <axis
      xyz="0 0 1" />
    <limit
      lower="0"
      upper="1"
      effort="1"
      velocity="1" />
  </joint>

  <link
    name="gripper_finger2_link2">
    <inertial>
      <origin
        xyz="-0.011366555972498 0.0118642725662323 -0.0060000073930068"
        rpy="0 0 0" />
      <mass
        value="0.0127543420299362" />
      <inertia
        ixx="5.68538478020238E-07"
        ixy="2.6801226272901E-07"
        ixz="9.34125986250171E-13"
        iyy="1.45145776457489E-06"
        iyz="-9.34355361631596E-13"
        izz="1.5056459822045E-06" />
    </inertial>
    <visual>
      <origin
        xyz="0 0 0"
        rpy="0 0 0" />
      <geometry>
        <mesh
          filename="/home/wangwei/ros2_ws/src/ros2_rm_robot/rm_description/meshes/gripper/Link22.STL" />
      </geometry>
      <material
        name="">
        <color
          rgba="0.894117647058823 0.913725490196078 0.929411764705882 1" />
      </material>
    </visual>
    <collision>
      <origin
        xyz="0 0 0"
        rpy="0 0 0" />
      <geometry>
        <mesh
          filename="/home/wangwei/ros2_ws/src/ros2_rm_robot/rm_description/meshes/gripper/Link22.STL" />
      </geometry>
    </collision>
  </link>
</robot>

